Workbook

Sheet MATRICE ML35 VIERGE
A1: NB JOURS MOIS | B1: 30 | C1: 46174 | Q1: Motifs
A2: SIRET | E2: FIXE 100% | H2: Périodes | L2: NB JRS | M2: MOTIFS | Q2: ML35
A3: N°SS | E3: P.TRANS | H3: DU | J3: au | L3: =IF(I3>0,K3-I3+1,"") | Q3: CA
A4: MATRICULE | F4: =SUM(F2:F3) -> 0 | H4: DU | J4: au | L4: =IF(I4>0,K4-I4+1,"")
A5: NOM | E5: MAJO | H5: DU | J5: au | L5: =IF(I5>0,K5-I5+1,"")
A6: PRENOM | E6: PANIERS | H6: DU | J6: au | L6: =IF(I6>0,K6-I6+1,"")
A7: DATE AT | E7: TOTAL | F7: =SUM(F4:F6) -> 0 | H7: DU | J7: au | L7: =IF(I7>0,K7-I7+1,"")
A8: DJT | H8: DU | J8: au | L8: =IF(I8>0,K8-I8+1,"")
H9: DU | J9: au | L9: =IF(I9>0,K9-I9+1,"")
H10: DU | J10: au | L10: =IF(I10>0,K10-I10+1,"")
A13: PERTE | G13: soit | H13: PERTE A DECLARER | L13: 0.21
A14: IJ/ JOURS | B14: =+C17/B17 -> #DIV/0! | H14: =+IF(I3>0,I3,"") | I14: au | J14: =+IF(K3>0,K3,"") | K14: =IF(M3="ML35",$E$17*L3/$B$17,0) -> 0 | L14: =K14*$F$16 -> 0
H15: =+IF(I4>0,I4,"") | I15: au | J15: =+IF(K4>0,K4,"") | K15: =IF(M4="ML35",$E$17*L4/$B$17,0) -> 0 | L15: =K15*$F$16 -> 0
B16: NB JOURS | C16: IJ TOTAL TPT | D16: IGR | E16: TOTAL | F16: 0.21 | H16: =+IF(I5>0,I5,"") | I16: au | J16: =+IF(K5>0,K5,"") | K16: =IF(M5="ML35",$E$17*L5/$B$17,0) -> 0 | L16: =K16*$F$16 -> 0
A17: ML35 | B17: =SUMIF(M3:M10,"ML35",L3:L10) -> 0 | E17: =+C17+D17 -> 0 | F17: =+E17*F16 -> 0 | H17: =+IF(I6>0,I6,"") | I17: au | J17: =+IF(K6>0,K6,"") | K17: =IF(M6="ML35",$E$17*L6/$B$17,0) -> 0 | L17: =K17*$F$16 -> 0
H18: =+IF(I7>0,I7,"") | I18: au | J18: =+IF(K7>0,K7,"") | K18: =IF(M7="ML35",$E$17*L7/$B$17,0) -> 0 | L18: =K18*$F$16 -> 0
H19: =+IF(I8>0,I8,"") | I19: au | J19: =+IF(K8>0,K8,"") | K19: =IF(M8="ML35",$E$17*L8/$B$17,0) -> 0 | L19: =K19*$F$16 -> 0
H20: =+IF(I9>0,I9,"") | I20: au | J20: =+IF(K9>0,K9,"") | K20: =IF(M9="ML35",$E$17*L9/$B$17,0) -> 0 | L20: =K20*$F$16 -> 0
H21: =+IF(I10>0,I10,"") | I21: au | J21: =+IF(K10>0,K10,"") | K21: =IF(M10="ML35",$E$17*L10/$B$17,0) -> 0 | L21: =K21*$F$16 -> 0
A23: Perçu CPAM | H23: FIXE | I23: MAJO + PAN | J23: IJ RETIRER | K23: A DECLARER | L23: 0.21
A24: DU | B24: =+IF(I3>0,I3,"") | C24: au | D24: =+IF(K3>0,K3,"") | E24: =+IF(L3>0,L3,"") | F24: =+IF(M3>0,M3,"") | H24: =IF(L3=0,0,(($F$4/30)*(E24/$B$1*30))) -> #VALUE! | I24: =IF(F24="ML35",(($F$5+$F$6)/(SUMIF($M$3:$M$10,"ML35",$L$3:$L$10))*E24),0) -> 0 | J24: =K14 -> 0 | K24: =H24+I24-J24 -> #VALUE! | L24: =K24*L23 -> #VALUE!
A25: DU | B25: =+IF(I4>0,I4,"") | C25: au | D25: =+IF(K4>0,K4,"") | E25: =+IF(L4>0,L4,"") | F25: =+IF(M4>0,M4,"") | H25: =IF(L4=0,0,(($F$4/30)*(E25/$B$1*30))) -> #VALUE! | I25: =IF(F25="ML35",(($F$5+$F$6)/(SUMIF($M$3:$M$10,"ML35",$L$3:$L$10))*E25),0) -> 0 | J25: =K15 -> 0 | K25: =H25+I25-J25 -> #VALUE! | L25: =K25*$L$23 -> #VALUE!
A26: DU | B26: =+IF(I5>0,I5,"") | C26: au | D26: =+IF(K5>0,K5,"") | E26: =+IF(L5>0,L5,"") | F26: =+IF(M5>0,M5,"") | H26: =IF(L5=0,0,(($F$4/30)*(E26/$B$1*30))) -> #VALUE! | I26: =IF(F26="ML35",(($F$5+$F$6)/(SUMIF($M$3:$M$10,"ML35",$L$3:$L$10))*E26),0) -> 0 | J26: =K16 -> 0 | K26: =H26+I26-J26 -> #VALUE! | L26: =K26*$L$23 -> #VALUE!
A27: DU | B27: =+IF(I6>0,I6,"") | C27: au | D27: =+IF(K6>0,K6,"") | E27: =+IF(L6>0,L6,"") | F27: =+IF(M6>0,M6,"") | H27: =IF(L6=0,0,(($F$4/30)*(E27/$B$1*30))) -> #VALUE! | I27: =IF(F27="ML35",(($F$5+$F$6)/(SUMIF($M$3:$M$10,"ML35",$L$3:$L$10))*E27),0) -> 0 | J27: =K17 -> 0 | K27: =H27+I27-J27 -> #VALUE! | L27: =K27*$L$23 -> #VALUE!
A28: DU | B28: =+IF(I7>0,I7,"") | C28: au | D28: =+IF(K7>0,K7,"") | E28: =+IF(L7>0,L7,"") | F28: =+IF(M7>0,M7,"") | H28: =IF(L7=0,0,(($F$4/30)*(E28/$B$1*30))) -> #VALUE! | I28: =IF(F28="ML35",(($F$5+$F$6)/(SUMIF($M$3:$M$10,"ML35",$L$3:$L$10))*E28),0) -> 0 | J28: =K18 -> 0 | K28: =H28+I28-J28 -> #VALUE! | L28: =K28*$L$23 -> #VALUE!
A29: DU | B29: =+IF(I8>0,I8,"") | C29: au | D29: =+IF(K8>0,K8,"") | E29: =+IF(L8>0,L8,"") | F29: =+IF(M8>0,M8,"") | H29: =IF(L8=0,0,(($F$4/30)*(E29/$B$1*30))) -> #VALUE! | I29: =IF(F29="ML35",(($F$5+$F$6)/(SUMIF($M$3:$M$10,"ML35",$L$3:$L$10))*E29),0) -> 0 | J29: =K19 -> 0 | K29: =H29+I29-J29 -> #VALUE! | L29: =K29*$L$23 -> #VALUE!
A30: DU | B30: =+IF(I9>0,I9,"") | C30: au | D30: =+IF(K9>0,K9,"") | E30: =+IF(L9>0,L9,"") | F30: =+IF(M9>0,M9,"") | H30: =IF(L9=0,0,(($F$4/30)*(E30/$B$1*30))) -> #VALUE! | I30: =IF(F30="ML35",(($F$5+$F$6)/(SUMIF($M$3:$M$10,"ML35",$L$3:$L$10))*E30),0) -> 0 | J30: =K20 -> 0 | K30: =H30+I30-J30 -> #VALUE! | L30: =K30*$L$23 -> #VALUE!
A31: DU | B31: =+IF(I10>0,I10,"") | C31: au | D31: =+IF(K10>0,K10,"") | E31: =+IF(L10>0,L10,"") | F31: =+IF(M10>0,M10,"") | H31: =IF(L10=0,0,(($F$4/30)*(E31/$B$1*30))) -> #VALUE! | I31: =IF(F31="ML35",(($F$5+$F$6)/(SUMIF($M$3:$M$10,"ML35",$L$3:$L$10))*E31),0) -> 0 | J31: =K21 -> 0 | K31: =H31+I31-J31 -> #VALUE! | L31: =K31*$L$23 -> #VALUE!

Sheet MATRICE ML36 VIERGE
A1: SIRET | E1: MOIS | F1: 46174 | Q1: MOTIF | R1: MOTIF
A2: N°SS | E2: Nb jours dans le mois | F2: 30 | Q2: ML36 | R2: Maladie
A3: MATRICULE | R3: CA / JEM
A4: NOM | D4: SALAIRE RETABLI 3201 | F4: =($B$15*B8)+$E$15+$E$16-O6-O7-O8-O9-O10-O11-O12-O13-O14-O15+I23 -> 0 | I4: REPARTITION SELON ACTIVITE | R4: Autres absences
A5: PRENOM | H5: PERIODES | I5: MAJO | J5: PANIERS | K5: SIACI | N5: ABSENCE SANS SOLDE | R5: Abs sans solde
A6: DJT | H6: 1er PERIODE | I6: =IF($E$15<0,"",$E$15*(E21/($E$21+$E$26+$E$31+$E$36+$E$41+$E$46+$E$51+$E$56+$E$61+$E$66))) -> #DIV/0! | J6: =IF($E$16<0,"",$E$16*(E21/($E$21+$E$26+$E$31+$E$36+$E$41+$E$46+$E$51+$E$56+$E$61+$E$66))) -> #DIV/0! | K6: =IF($I$18<0,"",$I$18*(E21/($E$21+$E$26+$E$31+$E$36+$E$41+$E$46+$E$51+$E$56+$E$61+$E$66))) -> #DIV/0! | N6: 1er PERIODE | O6: =IF(A22="Abs sans solde",($B$15*((C22-B22+1)*30)/$F$2)/30,0) -> 0
H7: 2e PERIODE | I7: =IF($E$15<0,"",$E$15*(E26/($E$21+$E$26+$E$31+$E$36+$E$41+$E$46+$E$51+$E$56+$E$61+$E$66))) -> #DIV/0! | J7: =IF($E$16<0,"",$E$16*(E26/($E$21+$E$26+$E$31+$E$36+$E$41+$E$46+$E$51+$E$56+$E$61+$E$66))) -> #DIV/0! | K7: =IF($I$18<0,"",$I$18*(E26/($E$21+$E$26+$E$31+$E$36+$E$41+$E$46+$E$51+$E$56+$E$61+$E$66))) -> #DIV/0! | N7: 2e PERIODE | O7: =IF(A27="Abs sans solde",($B$15*((C27-B27+1)*30)/$F$2)/30,0) -> 0
A8: Taux initial | B8: 1 | C8: à taux TPT | D8: 0.4 | H8: 3e PERIODE | I8: =IF($E$15<0,"",$E$15*(E31/($E$21+$E$26+$E$31+$E$36+$E$41+$E$46+$E$51+$E$56+$E$61+$E$66))) -> #DIV/0! | J8: =IF($E$16<0,"",$E$16*(E31/($E$21+$E$26+$E$31+$E$36+$E$41+$E$46+$E$51+$E$56+$E$61+$E$66))) -> #DIV/0! | K8: =IF($I$18<0,"",$I$18*(E31/($E$21+$E$26+$E$31+$E$36+$E$41+$E$46+$E$51+$E$56+$E$61+$E$66))) -> #DIV/0! | N8: 3e PERIODE | O8: =IF(A32="Abs sans solde",($B$15*((C32-B32+1)*30)/$F$2)/30,0) -> 0
H9: 4e PERIODE | I9: =IF($E$15<0,"",$E$15*(E36/($E$21+$E$26+$E$31+$E$36+$E$41+$E$46+$E$51+$E$56+$E$61+$E$66))) -> #DIV/0! | J9: =IF($E$16<0,"",$E$16*(E36/($E$21+$E$26+$E$31+$E$36+$E$41+$E$46+$E$51+$E$56+$E$61+$E$66))) -> #DIV/0! | K9: =IF($I$18<0,"",$I$18*(E36/($E$21+$E$26+$E$31+$E$36+$E$41+$E$46+$E$51+$E$56+$E$61+$E$66))) -> #DIV/0! | N9: 4e PERIODE | O9: =IF(A37="Abs sans solde",($B$15*((C37-B37+1)*30)/$F$2)/30,0) -> 0
A10: TMF à 100% | D10: MAJ NUIT | H10: 5e PERIODE | I10: =IF($E$15<0,"",$E$15*(E41/($E$21+$E$26+$E$31+$E$36+$E$41+$E$46+$E$51+$E$56+$E$61+$E$66))) -> #DIV/0! | J10: =IF($E$16<0,"",$E$16*(E41/($E$21+$E$26+$E$31+$E$36+$E$41+$E$46+$E$51+$E$56+$E$61+$E$66))) -> #DIV/0! | K10: =IF($I$18<0,"",$I$18*(E41/($E$21+$E$26+$E$31+$E$36+$E$41+$E$46+$E$51+$E$56+$E$61+$E$66))) -> #DIV/0! | N10: 5e PERIODE | O10: =IF(A42="Abs sans solde",($B$15*((C42-B42+1)*30)/$F$2)/30,0) -> 0
A11: P.TRANSFERT à 100% | D11: maj ferie | H11: 6e PERIODE | I11: =IF($E$15<0,"",$E$15*(E46/($E$21+$E$26+$E$31+$E$36+$E$41+$E$46+$E$51+$E$56+$E$61+$E$66))) -> #DIV/0! | J11: =IF($E$16<0,"",$E$16*(E46/($E$21+$E$26+$E$31+$E$36+$E$41+$E$46+$E$51+$E$56+$E$61+$E$66))) -> #DIV/0! | K11: =IF($I$18<0,"",$I$18*(E46/($E$21+$E$26+$E$31+$E$36+$E$41+$E$46+$E$51+$E$56+$E$61+$E$66))) -> #DIV/0! | N11: 6e PERIODE | O11: =IF(A47="Abs sans solde",($B$15*((C47-B47+1)*30)/$F$2)/30,0) -> 0
H12: 7e PERIODE | I12: =IF($E$15<0,"",$E$15*(E51/($E$21+$E$26+$E$31+$E$36+$E$41+$E$46+$E$51+$E$56+$E$61+$E$66))) -> #DIV/0! | J12: =IF($E$16<0,"",$E$16*(E51/($E$21+$E$26+$E$31+$E$36+$E$41+$E$46+$E$51+$E$56+$E$61+$E$66))) -> #DIV/0! | K12: =IF($I$18<0,"",$I$18*(E51/($E$21+$E$26+$E$31+$E$36+$E$41+$E$46+$E$51+$E$56+$E$61+$E$66))) -> #DIV/0! | N12: 7e PERIODE | O12: =IF(A52="Abs sans solde",($B$15*((C52-B52+1)*30)/$F$2)/30,0) -> 0
H13: 8e PERIODE | I13: =IF($E$15<0,"",$E$15*(E56/($E$21+$E$26+$E$31+$E$36+$E$41+$E$46+$E$51+$E$56+$E$61+$E$66))) -> #DIV/0! | J13: =IF($E$16<0,"",$E$16*(E56/($E$21+$E$26+$E$31+$E$36+$E$41+$E$46+$E$51+$E$56+$E$61+$E$66))) -> #DIV/0! | K13: =IF($I$18<0,"",$I$18*(E56/($E$21+$E$26+$E$31+$E$36+$E$41+$E$46+$E$51+$E$56+$E$61+$E$66))) -> #DIV/0! | N13: 8e PERIODE | O13: =IF(A57="Abs sans solde",($B$15*((C57-B57+1)*30)/$F$2)/30,0) -> 0
H14: 9e PERIODE | I14: =IF($E$15<0,"",$E$15*(E61/($E$21+$E$26+$E$31+$E$36+$E$41+$E$46+$E$51+$E$56+$E$61+$E$66))) -> #DIV/0! | J14: =IF($E$16<0,"",$E$16*(E61/($E$21+$E$26+$E$31+$E$36+$E$41+$E$46+$E$51+$E$56+$E$61+$E$66))) -> #DIV/0! | K14: =IF($I$18<0,"",$I$18*(E61/($E$21+$E$26+$E$31+$E$36+$E$41+$E$46+$E$51+$E$56+$E$61+$E$66))) -> #DIV/0! | N14: 9e PERIODE | O14: =IF(A62="Abs sans solde",($B$15*((C62-B62+1)*30)/$F$2)/30,0) -> 0
B15: =SUM(B10:B14) -> 0 | E15: =SUM(E10:E14) -> 0 | H15: 10e PERIODE | I15: =IF($E$15<0,"",$E$15*(E66/($E$21+$E$26+$E$31+$E$36+$E$41+$E$46+$E$51+$E$56+$E$61+$E$66))) -> #DIV/0! | J15: =IF($E$16<0,"",$E$16*(E66/($E$21+$E$26+$E$31+$E$36+$E$41+$E$46+$E$51+$E$56+$E$61+$E$66))) -> #DIV/0! | K15: =IF($I$18<0,"",$I$18*(E66/($E$21+$E$26+$E$31+$E$36+$E$41+$E$46+$E$51+$E$56+$E$61+$E$66))) -> #DIV/0! | N15: 10e PERIODE | O15: =IF(A67="Abs sans solde",($B$15*((C67-B67+1)*30)/$F$2)/30,0) -> 0
D16: PANIERS + R226
H17: MONTANT SIACI =
H18: Montant qui a été réintégré | I18: =+I17*0.245 -> 0
A20: MOTIF | B20: Date début | C20: Date de fin | D20: Nb de jrs | E20: 30ème | F20: Dont PUA/PFA
D21: =IF(B21="",0,(C21-B21+1)) -> 0 | E21: =IF(D21=0,0,IF(OR($F$2=30,$F$2=D21),D21*30/$F$2,(D21*30/$F$2)+0.0005)) -> 0
A23: RETABLI | B23: =IF(A21="Abs (Mal, CA, autres)",0,($B$15*$B$8*E21)/30) -> 0 | D23: =IF(A21="Abs (Mal, CA, autres)",0,B23+$I$6+$J$6+F23) -> #DIV/0! | F23: =IF($I$23<0,"",$I$23*(E21/($E$21+$E$26+$E$31+$E$36+$E$41+$E$46+$E$51+$E$56+$E$61+$E$66))) -> #DIV/0! | H23: PUA =
A24: Perçu | B24: =IF(A21="Abs (Mal, CA, autres)",0,(($B$15*E21)/30)*$D$8) -> 0 | D24: =IF(A21="Abs (Mal, CA, autres)",0,(B24+I6+J6+F24+K6)) -> #DIV/0! | F24: =IF($I$24<0,"",$I$24*(E21/($E$21+$E$26+$E$31+$E$36+$E$41+$E$46+$E$51+$E$56+$E$61+$E$66))) -> #DIV/0! | H24: PUA PERCUE =
A25: PERTE | D25: =D23-D24 -> #DIV/0! | H25: PERTE = | I25: =I23-I24 -> 0
D26: =IF(B26="",0,(C26-B26+1)) -> 0 | E26: =IF(D26=0,0,IF(OR($F$2=30,$F$2=D26),D26*30/$F$2,(D26*30/$F$2)+0.0005)) -> 0
A28: RETABLI | B28: =IF(A26="Abs (Mal, CA, autres)",0,($B$15*$B$8*E26)/30) -> 0 | D28: =IF(A26="Abs (Mal, CA, autres)",0,B28+$I$7+$J$7+F28) -> #DIV/0! | F28: =IF($I$23<0,"",$I$23*(E26/($E$21+$E$26+$E$31+$E$36+$E$41+$E$46+$E$51+$E$56+$E$61+$E$66))) -> #DIV/0!
A29: Perçu | B29: =IF(A26="Abs (Mal, CA, autres)",0,(($B$15*E26)/30)*$D$8) -> 0 | D29: =IF(A26="Abs (Mal, CA, autres)",0,(B29+$I$7+J7+F29+K7)) -> #DIV/0! | F29: =IF($I$24<0,"",$I$24*(E26/($E$21+$E$26+$E$31+$E$36+$E$41+$E$46+$E$51+$E$56+$E$61+$E$66))) -> #DIV/0!
A30: PERTE | D30: =D28-D29 -> #DIV/0!
D31: =IF(B31="",0,(C31-B31+1)) -> 0 | E31: =IF(D31=0,0,IF(OR($F$2=30,$F$2=D31),D31*30/$F$2,(D31*30/$F$2)+0.0005)) -> 0 | H31: AUTRES PRIMES =
A33: RETABLI | B33: =IF(A31="Abs (Mal, CA, autres)",0,($B$15*$B$8*E31)/30) -> 0 | D33: =IF(A31="Abs (Mal, CA, autres)",0,B33+$I$8+$J$8+F33) -> #DIV/0! | F33: =IF($I$23<0,"",$I$23*(E31/($E$21+$E$26+$E$31+$E$36+$E$41+$E$46+$E$51+$E$56+$E$61+$E$66))) -> #DIV/0!
A34: Perçu | B34: =IF(A31="Abs (Mal, CA, autres)",0,(($B$15*E31)/30)*$D$8) -> 0 | D34: =IF(A31="Abs (Mal, CA, autres)",0,(B34+$I$8+J8+F34+K8)) -> #DIV/0! | F34: =IF($I$24<0,"",$I$24*(E31/($E$21+$E$26+$E$31+$E$36+$E$41+$E$46+$E$51+$E$56+$E$61+$E$66))) -> #DIV/0!
A35: PERTE | D35: =D33-D34 -> #DIV/0!
D36: =IF(B36="",0,(C36-B36+1)) -> 0 | E36: =IF(D36=0,0,IF(OR($F$2=30,$F$2=D36),D36*30/$F$2,(D36*30/$F$2)+0.0005)) -> 0
A38: RETABLI | B38: =IF(A36="Abs (Mal, CA, autres)",0,($B$15*$B$8*E36)/30) -> 0 | D38: =IF(A36="Abs (Mal, CA, autres)",0,B38+$I$9+$J$9+F38) -> #DIV/0! | F38: =IF($I$23<0,"",$I$23*(E36/($E$21+$E$26+$E$31+$E$36+$E$41+$E$46+$E$51+$E$56+$E$61+$E$66))) -> #DIV/0!
A39: Perçu | B39: =IF(A36="Abs (Mal, CA, autres)",0,(($B$15*E36)/30)*$D$8) -> 0 | D39: =IF(A36="Abs (Mal, CA, autres)",0,(B39+$I$9+J9+F39+K9)) -> #DIV/0! | F39: =IF($I$24<0,"",$I$24*(E36/($E$21+$E$26+$E$31+$E$36+$E$41+$E$46+$E$51+$E$56+$E$61+$E$66))) -> #DIV/0!
A40: PERTE | D40: =D38-D39 -> #DIV/0!
D41: =IF(B41="",0,(C41-B41+1)) -> 0 | E41: =IF(D41=0,0,IF(OR($F$2=30,$F$2=D41),D41*30/$F$2,(D41*30/$F$2)+0.0005)) -> 0
A43: RETABLI | B43: =IF(A41="Abs (Mal, CA, autres)",0,($B$15*$B$8*E41)/30) -> 0 | D43: =IF(A41="Abs (Mal, CA, autres)",0,B43+$I$10+$J$10+F43) -> #DIV/0! | F43: =IF($I$23<0,"",$I$23*(E41/($E$21+$E$26+$E$31+$E$36+$E$41+$E$46+$E$51+$E$56+$E$61+$E$66))) -> #DIV/0!
A44: Perçu | B44: =IF(A41="Abs (Mal, CA, autres)",0,(($B$15*E41)/30)*$D$8) -> 0 | D44: =IF(A41="Abs (Mal, CA, autres)",0,(B44+$I$10+J10+F44+K10)) -> #DIV/0! | F44: =IF($I$24<0,"",$I$24*(E41/($E$21+$E$26+$E$31+$E$36+$E$41+$E$46+$E$51+$E$56+$E$61+$E$66))) -> #DIV/0!
A45: PERTE | D45: =D43-D44 -> #DIV/0!
D46: =IF(B46="",0,(C46-B46+1)) -> 0 | E46: =IF(D46=0,0,IF(OR($F$2=30,$F$2=D46),D46*30/$F$2,(D46*30/$F$2)+0.0005)) -> 0
...

Sheet MATRICE ML37 VIERGE
A1: SIRET | E1: MOIS | F1: 46174 | R1: MOTIF | S1: MOTIF
A2: N°SS | E2: Nb jours dans le mois | F2: 30 | R2: ML37 | S2: MALADIE
A3: MATRICULE | I3: REPARTITION SELON ACTIVITE | R3: CA | S3: JEM
A4: NOM | D4: SALAIRE RETABLI 3201 | F4: =($B$16*B9)+$E$17+$E$16-P6-P7-P8-P9-P10-P11-P12-P13-P14-P5+J23 -> 0 | J4: MAJO | K4: PANIERS | L4: SIACI | O4: ABSENCE SANS SOLDE | S4: Abs sans solde
A5: PRENOM | I5: 1E PERIODE | J5: =IF(A20="CA",0,IF($E$16<0,"",$E$16*(E20/($E$20+$E$25+$E$30+$E$35+$E$40+$E$45+$E$50+$E$55+$E$60+$E$65)))) -> #DIV/0! | K5: =IF($E$17<0,"",$E$17*(E20/($E$20+$E$25+$E$30+$E$35+$E$40+$E$45+$E$50+$E$55+$E$60+$E$65))) -> #DIV/0! | L5: =IF($J$20<0,"",$J$20*(E20/($E$20+$E$25+$E$30+$E$35+$E$40+$E$45+$E$50+$E$55+$E$60+$E$65))) -> #DIV/0! | O5: 1er PERIODE | P5: =IF(A21="Abs sans solde",($B$16*((C21-B21+1)*30)/$F$2)/30,0) -> 0
A6: DATE AT | I6: 2E PERIODE | J6: =IF(A25="CA",0,IF($E$16<0,"",$E$16*(E25/($E$20+$E$25+$E$30+$E$35+$E$40+$E$45+$E$50+$E$55+$E$60+$E$65)))) -> #DIV/0! | K6: =IF($E$17<0,"",$E$17*(E25/($E$20+$E$25+$E$30+$E$35+$E$40+$E$45+$E$50+$E$55+$E$60+$E$65))) -> #DIV/0! | L6: =IF($J$20<0,"",$J$20*(E25/($E$20+$E$25+$E$30+$E$35+$E$40+$E$45+$E$50+$E$55+$E$60+$E$65))) -> #DIV/0! | O6: 2e PERIODE | P6: =IF(A26="Abs sans solde",($B$16*((C26-B26+1)*30)/$F$2)/30,0) -> 0
A7: DJT | I7: 3E PERIODE | J7: =IF(A30="CA",0,IF($E$16<0,"",$E$16*(E30/($E$20+$E$25+$E$30+$E$35+$E$40+$E$45+$E$50+$E$55+$E$60+$E$65)))) -> #DIV/0! | K7: =IF($E$17<0,"",$E$17*(E30/($E$20+$E$25+$E$30+$E$35+$E$40+$E$45+$E$50+$E$55+$E$60+$E$65))) -> #DIV/0! | L7: =IF($J$20<0,"",$J$20*(E30/($E$20+$E$25+$E$30+$E$35+$E$40+$E$45+$E$50+$E$55+$E$60+$E$65))) -> #DIV/0! | O7: 3e PERIODE | P7: =IF(A31="Abs sans solde",($B$16*((C31-B31+1)*30)/$F$2)/30,0) -> 0
I8: 4E PERIODE | J8: =IF(A35="CA",0,IF($E$16<0,"",$E$16*(E35/($E$20+$E$25+$E$30+$E$35+$E$40+$E$45+$E$50+$E$55+$E$60+$E$65)))) -> #DIV/0! | K8: =IF($E$17<0,"",$E$17*(E35/($E$20+$E$25+$E$30+$E$35+$E$40+$E$45+$E$50+$E$55+$E$60+$E$65))) -> #DIV/0! | L8: =IF($J$20<0,"",$J$20*(E35/($E$20+$E$25+$E$30+$E$35+$E$40+$E$45+$E$50+$E$55+$E$60+$E$65))) -> #DIV/0! | O8: 4e PERIODE | P8: =IF(A36="Abs sans solde",($B$16*((C36-B36+1)*30)/$F$2)/30,0) -> 0
A9: Taux initial | B9: 1 | C9: à taux TPT | D9: 0.5 | I9: 5E PERIODE | J9: =IF(A40="CA",0,IF($E$16<0,"",$E$16*(E40/($E$20+$E$25+$E$30+$E$35+$E$40+$E$45+$E$50+$E$55+$E$60+$E$65)))) -> #DIV/0! | K9: =IF($E$17<0,"",$E$17*(E40/($E$20+$E$25+$E$30+$E$35+$E$40+$E$45+$E$50+$E$55+$E$60+$E$65))) -> #DIV/0! | L9: =IF($J$20<0,"",$J$20*(E40/($E$20+$E$25+$E$30+$E$35+$E$40+$E$45+$E$50+$E$55+$E$60+$E$65))) -> #DIV/0! | O9: 5e PERIODE | P9: =IF(A41="Abs sans solde",($B$16*((C41-B41+1)*30)/$F$2)/30,0) -> 0
I10: 6e PERIODE | J10: =IF(A45="CA",0,IF($E$16<0,"",$E$16*(E45/($E$20+$E$25+$E$30+$E$35+$E$40+$E$45+$E$50+$E$55+$E$60+$E$65)))) -> #DIV/0! | K10: =IF($E$17<0,"",$E$17*(E45/($E$20+$E$25+$E$30+$E$35+$E$40+$E$45+$E$50+$E$55+$E$60+$E$65))) -> #DIV/0! | L10: =IF($J$20<0,"",$J$20*(E45/($E$20+$E$25+$E$30+$E$35+$E$40+$E$45+$E$50+$E$55+$E$60+$E$65))) -> #DIV/0! | O10: 6e PERIODE | P10: =IF(A46="Abs sans solde",($B$16*((C46-B46+1)*30)/$F$2)/30,0) -> 0
A11: TMF à 100% | D11: REMU CA | I11: 7e PERIODE | J11: =IF(A50="CA",0,IF($E$16<0,"",$E$16*(E50/($E$20+$E$25+$E$30+$E$35+$E$40+$E$45+$E$50+$E$55+$E$60+$E$65)))) -> #DIV/0! | K11: =IF($E$17<0,"",$E$17*(E50/($E$20+$E$25+$E$30+$E$35+$E$40+$E$45+$E$50+$E$55+$E$60+$E$65))) -> #DIV/0! | L11: =IF($J$20<0,"",$J$20*(E50/($E$20+$E$25+$E$30+$E$35+$E$40+$E$45+$E$50+$E$55+$E$60+$E$65))) -> #DIV/0! | O11: 7e PERIODE | P11: =IF(A51="Abs sans solde",($B$16*((C51-B51+1)*30)/$F$2)/30,0) -> 0
A12: P.TRANSFERT à 100% | D12: MAJ NUIT | I12: 8e PERIODE | J12: =IF(A55="CA",0,IF($E$16<0,"",$E$16*(E55/($E$20+$E$25+$E$30+$E$35+$E$40+$E$45+$E$50+$E$55+$E$60+$E$65)))) -> #DIV/0! | K12: =IF($E$17<0,"",$E$17*(E55/($E$20+$E$25+$E$30+$E$35+$E$40+$E$45+$E$50+$E$55+$E$60+$E$65))) -> #DIV/0! | L12: =IF($J$20<0,"",$J$20*(E55/($E$20+$E$25+$E$30+$E$35+$E$40+$E$45+$E$50+$E$55+$E$60+$E$65))) -> #DIV/0! | O12: 8e PERIODE | P12: =IF(A56="Abs sans solde",($B$16*((C56-B56+1)*30)/$F$2)/30,0) -> 0
I13: 9e PERIODE | J13: =IF(A60="CA",0,IF($E$16<0,"",$E$16*(E60/($E$20+$E$25+$E$30+$E$35+$E$40+$E$45+$E$50+$E$55+$E$60+$E$65)))) -> #DIV/0! | K13: =IF($E$17<0,"",$E$17*(E60/($E$20+$E$25+$E$30+$E$35+$E$40+$E$45+$E$50+$E$55+$E$60+$E$65))) -> #DIV/0! | L13: =IF($J$20<0,"",$J$20*(E60/($E$20+$E$25+$E$30+$E$35+$E$40+$E$45+$E$50+$E$55+$E$60+$E$65))) -> #DIV/0! | O13: 9e PERIODE | P13: =IF(A61="Abs sans solde",($B$16*((C61-B61+1)*30)/$F$2)/30,0) -> 0
I14: 10e PERIODE | J14: =IF(A57="CA",0,IF($E$16<0,"",$E$16*(E65/($E$20+$E$25+$E$30+$E$35+$E$40+$E$45+$E$50+$E$55+$E$60+$E$65)))) -> #DIV/0! | K14: =IF($E$17<0,"",$E$17*(E65/($E$20+$E$25+$E$30+$E$35+$E$40+$E$45+$E$50+$E$55+$E$60+$E$65))) -> #DIV/0! | L14: =IF($J$20<0,"",$J$20*(E65/($E$20+$E$25+$E$30+$E$35+$E$40+$E$45+$E$50+$E$55+$E$60+$E$65))) -> #DIV/0! | O14: 10e PERIODE | P14: =IF(A66="Abs sans solde",($B$16*((C66-B66+1)*30)/$F$2)/30,0) -> 0
B16: =SUM(B11:B15) -> 0 | E16: =SUM(E11:E15) -> 0
D17: PANIERS+R226
A19: MOTIF | B19: Date début | C19: Date de fin | D19: Nb de jrs | E19: 30ème | F19: 0.21 | G19: Dont PUA/PFA | I19: MONTANT SIACI =
A20: ML37 | D20: =IF(B20="",0,(C20-B20+1)) -> 0 | E20: =IF(D20=0,0,IF(A20="CA",0,IF(OR($F$2=30,$F$2=D20),D20*30/$F$2,(D20*30/$F$2)+0.0005))) -> 0 | I20: Montant qui a été réintégré | J20: =+J19*0.245 -> 0
E21: =IF(D20=0,0,IF(A20="ML37",0,IF(OR($F$2=30,$F$2=D20),D20*30/$F$2,(D20*30/$F$2)+0.0005))) -> 0
A22: RETABLI | B22: =IF(A20="MALADIE",0,IF(A20="ML37",($B$16*$B$9*E20)/30,($B$16*$B$9*E21)/30)) -> 0 | D22: =IF(A20="MALADIE",0,IF(A20="ML37",B22+$J$5+K5+G22,0)) -> #DIV/0! | G22: =IF($J$23<0,"",$J$23*(E20/($E$20+$E$25+$E$30+$E$35+$E$40+$E$45+$E$50+$E$55+$E$60+$E$65))) -> #DIV/0!
A23: Perçu | B23: =IF(A20="MALADIE",0,IF(A20="ML37",((($B$16*E20)/30)*$D$9),B22)) -> 0 | D23: =IF(A20="MALADIE",0,IF(A20="ML37",(B23+J5+K5+L5+G23),B23)) -> #DIV/0! | F23: =+IF($E$20>0,D23*$F$19,B23*$F$19) -> 0 | G23: =IF($J$24<0,"",$J$24*(E20/($E$20+$E$25+$E$30+$E$35+$E$40+$E$45+$E$50+$E$55+$E$60+$E$65))) -> #DIV/0! | I23: PUA =
A24: PERTE | D24: =IF(D22=0,0,D22-D23) -> #DIV/0! | F24: =+IF($E$20>0,D24*$F$19,B24*$F$19) -> 0 | I24: PUA PERCUE =
D25: =IF(B25="",0,(C25-B25+1)) -> 0 | E25: =IF(D25=0,0,IF(A25="CA",0,IF(OR($F$2=30,$F$2=D25),D25*30/$F$2,(D25*30/$F$2)+0.0005))) -> 0 | I25: PERTE = | J25: =J23-J24 -> 0
E26: =IF(D25=0,0,IF(A25="ML37",0,IF(OR($F$2=30,$F$2=D25),D25*30/$F$2,(D25*30/$F$2)+0.0005))) -> 0
A27: RETABLI | B27: =IF(A25="MALADIE",0,IF(A25="ML37",($B$16*$B$9*E25)/30,($B$16*$B$9*E26)/30)) -> 0 | D27: =IF(A25="MALADIE",0,IF(A25="ML37",B27+$J$6+K6+G27,0)) -> 0 | G27: =IF($J$23<0,"",$J$23*(E25/($E$20+$E$25+$E$30+$E$35+$E$40+$E$45+$E$50+$E$55+$E$60+$E$65))) -> #DIV/0!
A28: Perçu | B28: =IF(A25="MALADIE",0,IF(A25="ML37",((($B$16*E25)/30)*$D$9),B27)) -> 0 | D28: =IF(A25="MALADIE",0,IF(A25="ML37",(B28+J6+K6+L6+G28),B28)) -> 0 | F28: =+IF($E$25>0,D28*$F$19,B28*$F$19) -> 0 | G28: =IF($J$24<0,"",$J$24*(E25/($E$20+$E$25+$E$30+$E$35+$E$40+$E$45+$E$50+$E$55+$E$60+$E$65))) -> #DIV/0!
A29: PERTE | D29: =IF(D27=0,0,D27-D28) -> 0 | F29: =+IF($E$25>0,D29*$F$19,B29*$F$19) -> 0
D30: =IF(B30="",0,(C30-B30+1)) -> 0 | E30: =IF(D30=0,0,IF(A30="CA",0,IF(OR($F$2=30,$F$2=D30),D30*30/$F$2,(D30*30/$F$2)+0.0005))) -> 0 | I30: AUTRES PRIMES =
E31: =IF(D30=0,0,IF(A30="ML37",0,IF(OR($F$2=30,$F$2=D30),D30*30/$F$2,(D30*30/$F$2)+0.0005))) -> 0
A32: RETABLI | B32: =IF(A30="MALADIE",0,IF(A30="ML37",($B$16*$B$9*E30)/30,($B$16*$B$9*E31)/30)) -> 0 | D32: =IF(A30="MALADIE",0,IF(A30="ML37",B32+$J$7+K7+G32,0)) -> 0 | G32: =IF($J$23<0,"",$J$23*(E30/($E$20+$E$25+$E$30+$E$35+$E$40+$E$45+$E$50+$E$55+$E$60+$E$65))) -> #DIV/0!
A33: Perçu | B33: =IF(A30="MALADIE",0,IF(A30="ML37",((($B$16*E30)/30)*$D$9),B32)) -> 0 | D33: =IF(A30="MALADIE",0,IF(A30="ML37",(B33+J7+K7+L7+G33),B33)) -> 0 | F33: =+IF($E$30>0,D33*$F$19,B33*$F$19) -> 0 | G33: =IF($J$24<0,"",$J$24*(E30/($E$20+$E$25+$E$30+$E$35+$E$40+$E$45+$E$50+$E$55+$E$60+$E$65))) -> #DIV/0!
A34: PERTE | D34: =IF(D32=0,0,D32-D33) -> 0 | F34: =+IF($E$30>0,D34*$F$19,B34*$F$19) -> 0
D35: =IF(B35="",0,(C35-B35+1)) -> 0 | E35: =IF(D35=0,0,IF(A35="CA",0,IF(OR($F$2=30,$F$2=D35),D35*30/$F$2,(D35*30/$F$2)+0.0005))) -> 0
E36: =IF(D35=0,0,IF(A35="ML37",0,IF(OR($F$2=30,$F$2=D35),D35*30/$F$2,(D35*30/$F$2)+0.0005))) -> 0
A37: RETABLI | B37: =IF(A35="MALADIE",0,IF(A35="ML37",($B$16*$B$9*E35)/30,($B$16*$B$9*E36)/30)) -> 0 | D37: =IF(A35="MALADIE",0,IF(A35="ML37",B37+$J$8+K8+G37,0)) -> 0 | G37: =IF($J$23<0,"",$J$23*(E35/($E$20+$E$25+$E$30+$E$35+$E$40+$E$45+$E$50+$E$55+$E$60+$E$65))) -> #DIV/0!
A38: Perçu | B38: =IF(A35="MALADIE",0,IF(A35="ML37",((($B$16*E35)/30)*$D$9),B37)) -> 0 | D38: =IF(A35="MALADIE",0,IF(A35="ML37",(B38+J8+K8+L8+G38),B38)) -> 0 | F38: =+IF($E$35>0,D38*$F$19,B38*$F$19) -> 0 | G38: =IF($J$24<0,"",$J$24*(E35/($E$20+$E$25+$E$30+$E$35+$E$40+$E$45+$E$50+$E$55+$E$60+$E$65))) -> #DIV/0!
A39: PERTE | D39: =IF(D37=0,0,D37-D38) -> 0 | F39: =+IF($E$35>0,D39*$F$19,B39*$F$19) -> 0
D40: =IF(B40="",0,(C40-B40+1)) -> 0 | E40: =IF(D40=0,0,IF(A40="CA",0,IF(OR($F$2=30,$F$2=D40),D40*30/$F$2,(D40*30/$F$2)+0.0005))) -> 0
E41: =IF(D40=0,0,IF(A40="ML37",0,IF(OR($F$2=30,$F$2=D40),D40*30/$F$2,(D40*30/$F$2)+0.0005))) -> 0
A42: RETABLI | B42: =IF(A40="MALADIE",0,IF(A40="ML37",($B$16*$B$9*E40)/30,($B$16*$B$9*E41)/30)) -> 0 | D42: =IF(A40="MALADIE",0,IF(A40="ML37",B42+$J$9+K9+G42,0)) -> 0 | G42: =IF($J$23<0,"",$J$23*(E40/($E$20+$E$25+$E$30+$E$35+$E$40+$E$45+$E$50+$E$55+$E$60+$E$65))) -> #DIV/0!
...

Sheet Attestation Vivinter
B3: ATTESTATION DE TEMPS PARTIEL
B5: RISQUES : | D5: INCAPACITE | H5: INVALIDITE
B7: Nous soussignés Société AIR FRANCE , attestons le salaire perçu pour le(s) mois cité(s) en référence ci-dessous en activité partielle.
B9: IDENTIFICATION DU SALARIE
B11: NOM | D11: =IF('MATRICE ML36 VIERGE'!B4<>"",'MATRICE ML36 VIERGE'!B4,IF('MATRICE ML37 VIERGE'!B4<>"",'MATRICE ML37 VIERGE'!B4,""))
B13: PRENOM | D13: =IF('MATRICE ML36 VIERGE'!B5<>"",'MATRICE ML36 VIERGE'!B5,IF('MATRICE ML37 VIERGE'!B5<>"",'MATRICE ML37 VIERGE'!B5,""))
B15: N° SECURITE SOCIALE | D15: =IF('MATRICE ML36 VIERGE'!B2<>"",'MATRICE ML36 VIERGE'!B2,IF('MATRICE ML37 VIERGE'!B2<>"",'MATRICE ML37 VIERGE'!B2,""))
B17: N° MATRICULE | D17: =IF('MATRICE ML36 VIERGE'!B3<>"",'MATRICE ML36 VIERGE'!B3,IF('MATRICE ML37 VIERGE'!B3<>"",'MATRICE ML37 VIERGE'!B3,""))
B19: N° DOSSIER
B21: QUALIFICATION | D21: PS | F21: PNC | H21: PNT
H23: Taux d'activité partielle (50%, 60 %, 80 %, etc…)
B24: Période de référence | D24: Salaires bruts soumis à cotisation | E24: Dont PUA / PFA | G24: Autres primes
B25: Du | C25: Au | D25: (1)
B26: =IF('MATRICE ML36 VIERGE'!B21<>"",TEXT('MATRICE ML36 VIERGE'!B21,"jj/mm/aaaa"),IF('MATRICE ML36 VIERGE'!B22<>"",TEXT('MATRICE ML36 VIERGE'!B22,"jj/mm/aaaa"),IF('MATRICE ML37 VIERGE'!B20<>"",TEXT('MATRICE ML37 VIERGE'!B20,"jj/mm/aaaa"),IF('MATRICE ML37 VIERGE'!B21<>"",TEXT('MATRICE ML37 VIERGE'!B21,"jj/mm/aaaa"),"")))) | C26: =IF('MATRICE ML36 VIERGE'!C21<>"",TEXT('MATRICE ML36 VIERGE'!C21,"jj/mm/aaaa"),IF('MATRICE ML36 VIERGE'!C22<>"",TEXT('MATRICE ML36 VIERGE'!C22,"jj/mm/aaaa"),IF('MATRICE ML37 VIERGE'!C20<>"",TEXT('MATRICE ML37 VIERGE'!C20,"jj/mm/aaaa"),IF('MATRICE ML37 VIERGE'!C21<>"",TEXT('MATRICE ML37 VIERGE'!C21,"jj/mm/aaaa"),"")))) | D26: =IF(OR('MATRICE ML36 VIERGE'!B21<>"",'MATRICE ML36 VIERGE'!B22<>""),IF(OR(ISNUMBER(SEARCH("maladie",'MATRICE ML36 VIERGE'!A21)),ISNUMBER(SEARCH("maladie",'MATRICE ML36 VIERGE'!A22))),"Maladie",IF(OR('MATRICE ML36 VIERGE'!A21="CA",'MATRICE ML36 VIERGE'!A22="CA",ISNUMBER(SEARCH("jem",'MATRICE ML36 VIERGE'!A21)),ISNUMBER(SEARCH("jem",'MATRICE ML36 VIERGE'!A22)),ISNUMBER(SEARCH("autres absence",'MATRICE ML36 VIERGE'!A21)),ISNUMBER(SEARCH("autres absence",'MATRICE ML36 VIERGE'!A22))),"Congés annuels",IF(OR(ISNUMBER(SEARCH("sans solde",'MATRICE ML36 VIERGE'!A21)),ISNUMBER(SEARCH("sans solde",'MATRICE ML36 VIERGE'!A22))),"Absence sans solde",IFERROR('MATRICE ML36 VIERGE'!F75,"")))),IF(OR('MATRICE ML37 VIERGE'!B20<>"",'MATRICE ML37 VIERGE'!B21<>""),IF(OR(ISNUMBER(SEARCH("maladie",'MATRICE ML37 VIERGE'!A20)),ISNUMBER(SEARCH("maladie",'MATRICE ML37 VIERGE'!A21))),"Maladie",IF(OR('MATRICE ML37 VIERGE'!A20="CA",'MATRICE ML37 VIERGE'!A21="CA",ISNUMBER(SEARCH("jem",'MATRICE ML37 VIERGE'!A20)),ISNUMBER(SEARCH("jem",'MATRICE ML37 VIERGE'!A21)),ISNUMBER(SEARCH("autres absence",'MATRICE ML37 VIERGE'!A20)),ISNUMBER(SEARCH("autres absence",'MATRICE ML37 VIERGE'!A21))),"Congés annuels",IF(OR(ISNUMBER(SEARCH("sans solde",'MATRICE ML37 VIERGE'!A20)),ISNUMBER(SEARCH("sans solde",'MATRICE ML37 VIERGE'!A21))),"Absence sans solde",IFERROR('MATRICE ML37 VIERGE'!F76,"")))),"")) | E26: =IF(OR('MATRICE ML36 VIERGE'!B21<>"",'MATRICE ML36 VIERGE'!B22<>""),IF(IFERROR('MATRICE ML36 VIERGE'!G75,0)=0,"",'MATRICE ML36 VIERGE'!G75),IF(OR('MATRICE ML37 VIERGE'!B20<>"",'MATRICE ML37 VIERGE'!B21<>""),IF(IFERROR('MATRICE ML37 VIERGE'!G76,0)=0,"",'MATRICE ML37 VIERGE'!G76),"")) | G26: =IF(OR('MATRICE ML36 VIERGE'!B21<>"",'MATRICE ML36 VIERGE'!B22<>""),IF(IFERROR('MATRICE ML36 VIERGE'!H75,0)=0,"",'MATRICE ML36 VIERGE'!H75),IF(OR('MATRICE ML37 VIERGE'!B20<>"",'MATRICE ML37 VIERGE'!B21<>""),IF(IFERROR('MATRICE ML37 VIERGE'!H76,0)=0,"",'MATRICE ML37 VIERGE'!H76),"")) | H26: =IF(OR(D26="",D26="Congés annuels",D26="Maladie",D26="Absence sans solde"),"",IF(OR('MATRICE ML36 VIERGE'!B21<>"",'MATRICE ML36 VIERGE'!B22<>""),IFERROR('MATRICE ML36 VIERGE'!$D$8,""),IF(OR('MATRICE ML37 VIERGE'!B20<>"",'MATRICE ML37 VIERGE'!B21<>""),IFERROR('MATRICE ML37 VIERGE'!$D$9,""),"")))
B27: =IF('MATRICE ML36 VIERGE'!B26<>"",TEXT('MATRICE ML36 VIERGE'!B26,"jj/mm/aaaa"),IF('MATRICE ML36 VIERGE'!B27<>"",TEXT('MATRICE ML36 VIERGE'!B27,"jj/mm/aaaa"),IF('MATRICE ML37 VIERGE'!B25<>"",TEXT('MATRICE ML37 VIERGE'!B25,"jj/mm/aaaa"),IF('MATRICE ML37 VIERGE'!B26<>"",TEXT('MATRICE ML37 VIERGE'!B26,"jj/mm/aaaa"),"")))) | C27: =IF('MATRICE ML36 VIERGE'!C26<>"",TEXT('MATRICE ML36 VIERGE'!C26,"jj/mm/aaaa"),IF('MATRICE ML36 VIERGE'!C27<>"",TEXT('MATRICE ML36 VIERGE'!C27,"jj/mm/aaaa"),IF('MATRICE ML37 VIERGE'!C25<>"",TEXT('MATRICE ML37 VIERGE'!C25,"jj/mm/aaaa"),IF('MATRICE ML37 VIERGE'!C26<>"",TEXT('MATRICE ML37 VIERGE'!C26,"jj/mm/aaaa"),"")))) | D27: =IF(OR('MATRICE ML36 VIERGE'!B26<>"",'MATRICE ML36 VIERGE'!B27<>""),IF(OR(ISNUMBER(SEARCH("maladie",'MATRICE ML36 VIERGE'!A26)),ISNUMBER(SEARCH("maladie",'MATRICE ML36 VIERGE'!A27))),"Maladie",IF(OR('MATRICE ML36 VIERGE'!A26="CA",'MATRICE ML36 VIERGE'!A27="CA",ISNUMBER(SEARCH("jem",'MATRICE ML36 VIERGE'!A26)),ISNUMBER(SEARCH("jem",'MATRICE ML36 VIERGE'!A27)),ISNUMBER(SEARCH("autres absence",'MATRICE ML36 VIERGE'!A26)),ISNUMBER(SEARCH("autres absence",'MATRICE ML36 VIERGE'!A27))),"Congés annuels",IF(OR(ISNUMBER(SEARCH("sans solde",'MATRICE ML36 VIERGE'!A26)),ISNUMBER(SEARCH("sans solde",'MATRICE ML36 VIERGE'!A27))),"Absence sans solde",IFERROR('MATRICE ML36 VIERGE'!F76,"")))),IF(OR('MATRICE ML37 VIERGE'!B25<>"",'MATRICE ML37 VIERGE'!B26<>""),IF(OR(ISNUMBER(SEARCH("maladie",'MATRICE ML37 VIERGE'!A25)),ISNUMBER(SEARCH("maladie",'MATRICE ML37 VIERGE'!A26))),"Maladie",IF(OR('MATRICE ML37 VIERGE'!A25="CA",'MATRICE ML37 VIERGE'!A26="CA",ISNUMBER(SEARCH("jem",'MATRICE ML37 VIERGE'!A25)),ISNUMBER(SEARCH("jem",'MATRICE ML37 VIERGE'!A26)),ISNUMBER(SEARCH("autres absence",'MATRICE ML37 VIERGE'!A25)),ISNUMBER(SEARCH("autres absence",'MATRICE ML37 VIERGE'!A26))),"Congés annuels",IF(OR(ISNUMBER(SEARCH("sans solde",'MATRICE ML37 VIERGE'!A25)),ISNUMBER(SEARCH("sans solde",'MATRICE ML37 VIERGE'!A26))),"Absence sans solde",IFERROR('MATRICE ML37 VIERGE'!F77,"")))),"")) | E27: =IF(OR('MATRICE ML36 VIERGE'!B26<>"",'MATRICE ML36 VIERGE'!B27<>""),IF(IFERROR('MATRICE ML36 VIERGE'!G76,0)=0,"",'MATRICE ML36 VIERGE'!G76),IF(OR('MATRICE ML37 VIERGE'!B25<>"",'MATRICE ML37 VIERGE'!B26<>""),IF(IFERROR('MATRICE ML37 VIERGE'!G77,0)=0,"",'MATRICE ML37 VIERGE'!G77),"")) | G27: =IF(OR('MATRICE ML36 VIERGE'!B26<>"",'MATRICE ML36 VIERGE'!B27<>""),IF(IFERROR('MATRICE ML36 VIERGE'!H76,0)=0,"",'MATRICE ML36 VIERGE'!H76),IF(OR('MATRICE ML37 VIERGE'!B25<>"",'MATRICE ML37 VIERGE'!B26<>""),IF(IFERROR('MATRICE ML37 VIERGE'!H77,0)=0,"",'MATRICE ML37 VIERGE'!H77),"")) | H27: =IF(OR(D27="",D27="Congés annuels",D27="Maladie",D27="Absence sans solde"),"",IF(OR('MATRICE ML36 VIERGE'!B26<>"",'MATRICE ML36 VIERGE'!B27<>""),IFERROR('MATRICE ML36 VIERGE'!$D$8,""),IF(OR('MATRICE ML37 VIERGE'!B25<>"",'MATRICE ML37 VIERGE'!B26<>""),IFERROR('MATRICE ML37 VIERGE'!$D$9,""),"")))
B28: =IF('MATRICE ML36 VIERGE'!B31<>"",TEXT('MATRICE ML36 VIERGE'!B31,"jj/mm/aaaa"),IF('MATRICE ML36 VIERGE'!B32<>"",TEXT('MATRICE ML36 VIERGE'!B32,"jj/mm/aaaa"),IF('MATRICE ML37 VIERGE'!B30<>"",TEXT('MATRICE ML37 VIERGE'!B30,"jj/mm/aaaa"),IF('MATRICE ML37 VIERGE'!B31<>"",TEXT('MATRICE ML37 VIERGE'!B31,"jj/mm/aaaa"),"")))) | C28: =IF('MATRICE ML36 VIERGE'!C31<>"",TEXT('MATRICE ML36 VIERGE'!C31,"jj/mm/aaaa"),IF('MATRICE ML36 VIERGE'!C32<>"",TEXT('MATRICE ML36 VIERGE'!C32,"jj/mm/aaaa"),IF('MATRICE ML37 VIERGE'!C30<>"",TEXT('MATRICE ML37 VIERGE'!C30,"jj/mm/aaaa"),IF('MATRICE ML37 VIERGE'!C31<>"",TEXT('MATRICE ML37 VIERGE'!C31,"jj/mm/aaaa"),"")))) | D28: =IF(OR('MATRICE ML36 VIERGE'!B31<>"",'MATRICE ML36 VIERGE'!B32<>""),IF(OR(ISNUMBER(SEARCH("maladie",'MATRICE ML36 VIERGE'!A31)),ISNUMBER(SEARCH("maladie",'MATRICE ML36 VIERGE'!A32))),"Maladie",IF(OR('MATRICE ML36 VIERGE'!A31="CA",'MATRICE ML36 VIERGE'!A32="CA",ISNUMBER(SEARCH("jem",'MATRICE ML36 VIERGE'!A31)),ISNUMBER(SEARCH("jem",'MATRICE ML36 VIERGE'!A32)),ISNUMBER(SEARCH("autres absence",'MATRICE ML36 VIERGE'!A31)),ISNUMBER(SEARCH("autres absence",'MATRICE ML36 VIERGE'!A32))),"Congés annuels",IF(OR(ISNUMBER(SEARCH("sans solde",'MATRICE ML36 VIERGE'!A31)),ISNUMBER(SEARCH("sans solde",'MATRICE ML36 VIERGE'!A32))),"Absence sans solde",IFERROR('MATRICE ML36 VIERGE'!F77,"")))),IF(OR('MATRICE ML37 VIERGE'!B30<>"",'MATRICE ML37 VIERGE'!B31<>""),IF(OR(ISNUMBER(SEARCH("maladie",'MATRICE ML37 VIERGE'!A30)),ISNUMBER(SEARCH("maladie",'MATRICE ML37 VIERGE'!A31))),"Maladie",IF(OR('MATRICE ML37 VIERGE'!A30="CA",'MATRICE ML37 VIERGE'!A31="CA",ISNUMBER(SEARCH("jem",'MATRICE ML37 VIERGE'!A30)),ISNUMBER(SEARCH("jem",'MATRICE ML37 VIERGE'!A31)),ISNUMBER(SEARCH("autres absence",'MATRICE ML37 VIERGE'!A30)),ISNUMBER(SEARCH("autres absence",'MATRICE ML37 VIERGE'!A31))),"Congés annuels",IF(OR(ISNUMBER(SEARCH("sans solde",'MATRICE ML37 VIERGE'!A30)),ISNUMBER(SEARCH("sans solde",'MATRICE ML37 VIERGE'!A31))),"Absence sans solde",IFERROR('MATRICE ML37 VIERGE'!F78,"")))),"")) | E28: =IF(OR('MATRICE ML36 VIERGE'!B31<>"",'MATRICE ML36 VIERGE'!B32<>""),IF(IFERROR('MATRICE ML36 VIERGE'!G77,0)=0,"",'MATRICE ML36 VIERGE'!G77),IF(OR('MATRICE ML37 VIERGE'!B30<>"",'MATRICE ML37 VIERGE'!B31<>""),IF(IFERROR('MATRICE ML37 VIERGE'!G78,0)=0,"",'MATRICE ML37 VIERGE'!G78),"")) | G28: =IF(OR('MATRICE ML36 VIERGE'!B31<>"",'MATRICE ML36 VIERGE'!B32<>""),IF(IFERROR('MATRICE ML36 VIERGE'!H77,0)=0,"",'MATRICE ML36 VIERGE'!H77),IF(OR('MATRICE ML37 VIERGE'!B30<>"",'MATRICE ML37 VIERGE'!B31<>""),IF(IFERROR('MATRICE ML37 VIERGE'!H78,0)=0,"",'MATRICE ML37 VIERGE'!H78),"")) | H28: =IF(OR(D28="",D28="Congés annuels",D28="Maladie",D28="Absence sans solde"),"",IF(OR('MATRICE ML36 VIERGE'!B31<>"",'MATRICE ML36 VIERGE'!B32<>""),IFERROR('MATRICE ML36 VIERGE'!$D$8,""),IF(OR('MATRICE ML37 VIERGE'!B30<>"",'MATRICE ML37 VIERGE'!B31<>""),IFERROR('MATRICE ML37 VIERGE'!$D$9,""),"")))
B29: =IF('MATRICE ML36 VIERGE'!B36<>"",TEXT('MATRICE ML36 VIERGE'!B36,"jj/mm/aaaa"),IF('MATRICE ML36 VIERGE'!B37<>"",TEXT('MATRICE ML36 VIERGE'!B37,"jj/mm/aaaa"),IF('MATRICE ML37 VIERGE'!B35<>"",TEXT('MATRICE ML37 VIERGE'!B35,"jj/mm/aaaa"),IF('MATRICE ML37 VIERGE'!B36<>"",TEXT('MATRICE ML37 VIERGE'!B36,"jj/mm/aaaa"),"")))) | C29: =IF('MATRICE ML36 VIERGE'!C36<>"",TEXT('MATRICE ML36 VIERGE'!C36,"jj/mm/aaaa"),IF('MATRICE ML36 VIERGE'!C37<>"",TEXT('MATRICE ML36 VIERGE'!C37,"jj/mm/aaaa"),IF('MATRICE ML37 VIERGE'!C35<>"",TEXT('MATRICE ML37 VIERGE'!C35,"jj/mm/aaaa"),IF('MATRICE ML37 VIERGE'!C36<>"",TEXT('MATRICE ML37 VIERGE'!C36,"jj/mm/aaaa"),"")))) | D29: =IF(OR('MATRICE ML36 VIERGE'!B36<>"",'MATRICE ML36 VIERGE'!B37<>""),IF(OR(ISNUMBER(SEARCH("maladie",'MATRICE ML36 VIERGE'!A36)),ISNUMBER(SEARCH("maladie",'MATRICE ML36 VIERGE'!A37))),"Maladie",IF(OR('MATRICE ML36 VIERGE'!A36="CA",'MATRICE ML36 VIERGE'!A37="CA",ISNUMBER(SEARCH("jem",'MATRICE ML36 VIERGE'!A36)),ISNUMBER(SEARCH("jem",'MATRICE ML36 VIERGE'!A37)),ISNUMBER(SEARCH("autres absence",'MATRICE ML36 VIERGE'!A36)),ISNUMBER(SEARCH("autres absence",'MATRICE ML36 VIERGE'!A37))),"Congés annuels",IF(OR(ISNUMBER(SEARCH("sans solde",'MATRICE ML36 VIERGE'!A36)),ISNUMBER(SEARCH("sans solde",'MATRICE ML36 VIERGE'!A37))),"Absence sans solde",IFERROR('MATRICE ML36 VIERGE'!F78,"")))),IF(OR('MATRICE ML37 VIERGE'!B35<>"",'MATRICE ML37 VIERGE'!B36<>""),IF(OR(ISNUMBER(SEARCH("maladie",'MATRICE ML37 VIERGE'!A35)),ISNUMBER(SEARCH("maladie",'MATRICE ML37 VIERGE'!A36))),"Maladie",IF(OR('MATRICE ML37 VIERGE'!A35="CA",'MATRICE ML37 VIERGE'!A36="CA",ISNUMBER(SEARCH("jem",'MATRICE ML37 VIERGE'!A35)),ISNUMBER(SEARCH("jem",'MATRICE ML37 VIERGE'!A36)),ISNUMBER(SEARCH("autres absence",'MATRICE ML37 VIERGE'!A35)),ISNUMBER(SEARCH("autres absence",'MATRICE ML37 VIERGE'!A36))),"Congés annuels",IF(OR(ISNUMBER(SEARCH("sans solde",'MATRICE ML37 VIERGE'!A35)),ISNUMBER(SEARCH("sans solde",'MATRICE ML37 VIERGE'!A36))),"Absence sans solde",IFERROR('MATRICE ML37 VIERGE'!F79,"")))),"")) | E29: =IF(OR('MATRICE ML36 VIERGE'!B36<>"",'MATRICE ML36 VIERGE'!B37<>""),IF(IFERROR('MATRICE ML36 VIERGE'!G78,0)=0,"",'MATRICE ML36 VIERGE'!G78),IF(OR('MATRICE ML37 VIERGE'!B35<>"",'MATRICE ML37 VIERGE'!B36<>""),IF(IFERROR('MATRICE ML37 VIERGE'!G79,0)=0,"",'MATRICE ML37 VIERGE'!G79),"")) | G29: =IF(OR('MATRICE ML36 VIERGE'!B36<>"",'MATRICE ML36 VIERGE'!B37<>""),IF(IFERROR('MATRICE ML36 VIERGE'!H78,0)=0,"",'MATRICE ML36 VIERGE'!H78),IF(OR('MATRICE ML37 VIERGE'!B35<>"",'MATRICE ML37 VIERGE'!B36<>""),IF(IFERROR('MATRICE ML37 VIERGE'!H79,0)=0,"",'MATRICE ML37 VIERGE'!H79),"")) | H29: =IF(OR(D29="",D29="Congés annuels",D29="Maladie",D29="Absence sans solde"),"",IF(OR('MATRICE ML36 VIERGE'!B36<>"",'MATRICE ML36 VIERGE'!B37<>""),IFERROR('MATRICE ML36 VIERGE'!$D$8,""),IF(OR('MATRICE ML37 VIERGE'!B35<>"",'MATRICE ML37 VIERGE'!B36<>""),IFERROR('MATRICE ML37 VIERGE'!$D$9,""),"")))
B30: =IF('MATRICE ML36 VIERGE'!B41<>"",TEXT('MATRICE ML36 VIERGE'!B41,"jj/mm/aaaa"),IF('MATRICE ML36 VIERGE'!B42<>"",TEXT('MATRICE ML36 VIERGE'!B42,"jj/mm/aaaa"),IF('MATRICE ML37 VIERGE'!B40<>"",TEXT('MATRICE ML37 VIERGE'!B40,"jj/mm/aaaa"),IF('MATRICE ML37 VIERGE'!B41<>"",TEXT('MATRICE ML37 VIERGE'!B41,"jj/mm/aaaa"),"")))) | C30: =IF('MATRICE ML36 VIERGE'!C41<>"",TEXT('MATRICE ML36 VIERGE'!C41,"jj/mm/aaaa"),IF('MATRICE ML36 VIERGE'!C42<>"",TEXT('MATRICE ML36 VIERGE'!C42,"jj/mm/aaaa"),IF('MATRICE ML37 VIERGE'!C40<>"",TEXT('MATRICE ML37 VIERGE'!C40,"jj/mm/aaaa"),IF('MATRICE ML37 VIERGE'!C41<>"",TEXT('MATRICE ML37 VIERGE'!C41,"jj/mm/aaaa"),"")))) | D30: =IF(OR('MATRICE ML36 VIERGE'!B41<>"",'MATRICE ML36 VIERGE'!B42<>""),IF(OR(ISNUMBER(SEARCH("maladie",'MATRICE ML36 VIERGE'!A41)),ISNUMBER(SEARCH("maladie",'MATRICE ML36 VIERGE'!A42))),"Maladie",IF(OR('MATRICE ML36 VIERGE'!A41="CA",'MATRICE ML36 VIERGE'!A42="CA",ISNUMBER(SEARCH("jem",'MATRICE ML36 VIERGE'!A41)),ISNUMBER(SEARCH("jem",'MATRICE ML36 VIERGE'!A42)),ISNUMBER(SEARCH("autres absence",'MATRICE ML36 VIERGE'!A41)),ISNUMBER(SEARCH("autres absence",'MATRICE ML36 VIERGE'!A42))),"Congés annuels",IF(OR(ISNUMBER(SEARCH("sans solde",'MATRICE ML36 VIERGE'!A41)),ISNUMBER(SEARCH("sans solde",'MATRICE ML36 VIERGE'!A42))),"Absence sans solde",IFERROR('MATRICE ML36 VIERGE'!F79,"")))),IF(OR('MATRICE ML37 VIERGE'!B40<>"",'MATRICE ML37 VIERGE'!B41<>""),IF(OR(ISNUMBER(SEARCH("maladie",'MATRICE ML37 VIERGE'!A40)),ISNUMBER(SEARCH("maladie",'MATRICE ML37 VIERGE'!A41))),"Maladie",IF(OR('MATRICE ML37 VIERGE'!A40="CA",'MATRICE ML37 VIERGE'!A41="CA",ISNUMBER(SEARCH("jem",'MATRICE ML37 VIERGE'!A40)),ISNUMBER(SEARCH("jem",'MATRICE ML37 VIERGE'!A41)),ISNUMBER(SEARCH("autres absence",'MATRICE ML37 VIERGE'!A40)),ISNUMBER(SEARCH("autres absence",'MATRICE ML37 VIERGE'!A41))),"Congés annuels",IF(OR(ISNUMBER(SEARCH("sans solde",'MATRICE ML37 VIERGE'!A40)),ISNUMBER(SEARCH("sans solde",'MATRICE ML37 VIERGE'!A41))),"Absence sans solde",IFERROR('MATRICE ML37 VIERGE'!F80,"")))),"")) | E30: =IF(OR('MATRICE ML36 VIERGE'!B41<>"",'MATRICE ML36 VIERGE'!B42<>""),IF(IFERROR('MATRICE ML36 VIERGE'!G79,0)=0,"",'MATRICE ML36 VIERGE'!G79),IF(OR('MATRICE ML37 VIERGE'!B40<>"",'MATRICE ML37 VIERGE'!B41<>""),IF(IFERROR('MATRICE ML37 VIERGE'!G80,0)=0,"",'MATRICE ML37 VIERGE'!G80),"")) | G30: =IF(OR('MATRICE ML36 VIERGE'!B41<>"",'MATRICE ML36 VIERGE'!B42<>""),IF(IFERROR('MATRICE ML36 VIERGE'!H79,0)=0,"",'MATRICE ML36 VIERGE'!H79),IF(OR('MATRICE ML37 VIERGE'!B40<>"",'MATRICE ML37 VIERGE'!B41<>""),IF(IFERROR('MATRICE ML37 VIERGE'!H80,0)=0,"",'MATRICE ML37 VIERGE'!H80),"")) | H30: =IF(OR(D30="",D30="Congés annuels",D30="Maladie",D30="Absence sans solde"),"",IF(OR('MATRICE ML36 VIERGE'!B41<>"",'MATRICE ML36 VIERGE'!B42<>""),IFERROR('MATRICE ML36 VIERGE'!$D$8,""),IF(OR('MATRICE ML37 VIERGE'!B40<>"",'MATRICE ML37 VIERGE'!B41<>""),IFERROR('MATRICE ML37 VIERGE'!$D$9,""),"")))
B31: =IF('MATRICE ML36 VIERGE'!B46<>"",TEXT('MATRICE ML36 VIERGE'!B46,"jj/mm/aaaa"),IF('MATRICE ML36 VIERGE'!B47<>"",TEXT('MATRICE ML36 VIERGE'!B47,"jj/mm/aaaa"),IF('MATRICE ML37 VIERGE'!B45<>"",TEXT('MATRICE ML37 VIERGE'!B45,"jj/mm/aaaa"),IF('MATRICE ML37 VIERGE'!B46<>"",TEXT('MATRICE ML37 VIERGE'!B46,"jj/mm/aaaa"),"")))) | C31: =IF('MATRICE ML36 VIERGE'!C46<>"",TEXT('MATRICE ML36 VIERGE'!C46,"jj/mm/aaaa"),IF('MATRICE ML36 VIERGE'!C47<>"",TEXT('MATRICE ML36 VIERGE'!C47,"jj/mm/aaaa"),IF('MATRICE ML37 VIERGE'!C45<>"",TEXT('MATRICE ML37 VIERGE'!C45,"jj/mm/aaaa"),IF('MATRICE ML37 VIERGE'!C46<>"",TEXT('MATRICE ML37 VIERGE'!C46,"jj/mm/aaaa"),"")))) | D31: =IF(OR('MATRICE ML36 VIERGE'!B46<>"",'MATRICE ML36 VIERGE'!B47<>""),IF(OR(ISNUMBER(SEARCH("maladie",'MATRICE ML36 VIERGE'!A46)),ISNUMBER(SEARCH("maladie",'MATRICE ML36 VIERGE'!A47))),"Maladie",IF(OR('MATRICE ML36 VIERGE'!A46="CA",'MATRICE ML36 VIERGE'!A47="CA",ISNUMBER(SEARCH("jem",'MATRICE ML36 VIERGE'!A46)),ISNUMBER(SEARCH("jem",'MATRICE ML36 VIERGE'!A47)),ISNUMBER(SEARCH("autres absence",'MATRICE ML36 VIERGE'!A46)),ISNUMBER(SEARCH("autres absence",'MATRICE ML36 VIERGE'!A47))),"Congés annuels",IF(OR(ISNUMBER(SEARCH("sans solde",'MATRICE ML36 VIERGE'!A46)),ISNUMBER(SEARCH("sans solde",'MATRICE ML36 VIERGE'!A47))),"Absence sans solde",IFERROR('MATRICE ML36 VIERGE'!F80,"")))),IF(OR('MATRICE ML37 VIERGE'!B45<>"",'MATRICE ML37 VIERGE'!B46<>""),IF(OR(ISNUMBER(SEARCH("maladie",'MATRICE ML37 VIERGE'!A45)),ISNUMBER(SEARCH("maladie",'MATRICE ML37 VIERGE'!A46))),"Maladie",IF(OR('MATRICE ML37 VIERGE'!A45="CA",'MATRICE ML37 VIERGE'!A46="CA",ISNUMBER(SEARCH("jem",'MATRICE ML37 VIERGE'!A45)),ISNUMBER(SEARCH("jem",'MATRICE ML37 VIERGE'!A46)),ISNUMBER(SEARCH("autres absence",'MATRICE ML37 VIERGE'!A45)),ISNUMBER(SEARCH("autres absence",'MATRICE ML37 VIERGE'!A46))),"Congés annuels",IF(OR(ISNUMBER(SEARCH("sans solde",'MATRICE ML37 VIERGE'!A45)),ISNUMBER(SEARCH("sans solde",'MATRICE ML37 VIERGE'!A46))),"Absence sans solde",IFERROR('MATRICE ML37 VIERGE'!F81,"")))),"")) | E31: =IF(OR('MATRICE ML36 VIERGE'!B46<>"",'MATRICE ML36 VIERGE'!B47<>""),IF(IFERROR('MATRICE ML36 VIERGE'!G80,0)=0,"",'MATRICE ML36 VIERGE'!G80),IF(OR('MATRICE ML37 VIERGE'!B45<>"",'MATRICE ML37 VIERGE'!B46<>""),IF(IFERROR('MATRICE ML37 VIERGE'!G81,0)=0,"",'MATRICE ML37 VIERGE'!G81),"")) | G31: =IF(OR('MATRICE ML36 VIERGE'!B46<>"",'MATRICE ML36 VIERGE'!B47<>""),IF(IFERROR('MATRICE ML36 VIERGE'!H80,0)=0,"",'MATRICE ML36 VIERGE'!H80),IF(OR('MATRICE ML37 VIERGE'!B45<>"",'MATRICE ML37 VIERGE'!B46<>""),IF(IFERROR('MATRICE ML37 VIERGE'!H81,0)=0,"",'MATRICE ML37 VIERGE'!H81),"")) | H31: =IF(OR(D31="",D31="Congés annuels",D31="Maladie",D31="Absence sans solde"),"",IF(OR('MATRICE ML36 VIERGE'!B46<>"",'MATRICE ML36 VIERGE'!B47<>""),IFERROR('MATRICE ML36 VIERGE'!$D$8,""),IF(OR('MATRICE ML37 VIERGE'!B45<>"",'MATRICE ML37 VIERGE'!B46<>""),IFERROR('MATRICE ML37 VIERGE'!$D$9,""),"")))
B32: =IF('MATRICE ML36 VIERGE'!B51<>"",TEXT('MATRICE ML36 VIERGE'!B51,"jj/mm/aaaa"),IF('MATRICE ML36 VIERGE'!B52<>"",TEXT('MATRICE ML36 VIERGE'!B52,"jj/mm/aaaa"),IF('MATRICE ML37 VIERGE'!B50<>"",TEXT('MATRICE ML37 VIERGE'!B50,"jj/mm/aaaa"),IF('MATRICE ML37 VIERGE'!B51<>"",TEXT('MATRICE ML37 VIERGE'!B51,"jj/mm/aaaa"),"")))) | C32: =IF('MATRICE ML36 VIERGE'!C51<>"",TEXT('MATRICE ML36 VIERGE'!C51,"jj/mm/aaaa"),IF('MATRICE ML36 VIERGE'!C52<>"",TEXT('MATRICE ML36 VIERGE'!C52,"jj/mm/aaaa"),IF('MATRICE ML37 VIERGE'!C50<>"",TEXT('MATRICE ML37 VIERGE'!C50,"jj/mm/aaaa"),IF('MATRICE ML37 VIERGE'!C51<>"",TEXT('MATRICE ML37 VIERGE'!C51,"jj/mm/aaaa"),"")))) | D32: =IF(OR('MATRICE ML36 VIERGE'!B51<>"",'MATRICE ML36 VIERGE'!B52<>""),IF(OR(ISNUMBER(SEARCH("maladie",'MATRICE ML36 VIERGE'!A51)),ISNUMBER(SEARCH("maladie",'MATRICE ML36 VIERGE'!A52))),"Maladie",IF(OR('MATRICE ML36 VIERGE'!A51="CA",'MATRICE ML36 VIERGE'!A52="CA",ISNUMBER(SEARCH("jem",'MATRICE ML36 VIERGE'!A51)),ISNUMBER(SEARCH("jem",'MATRICE ML36 VIERGE'!A52)),ISNUMBER(SEARCH("autres absence",'MATRICE ML36 VIERGE'!A51)),ISNUMBER(SEARCH("autres absence",'MATRICE ML36 VIERGE'!A52))),"Congés annuels",IF(OR(ISNUMBER(SEARCH("sans solde",'MATRICE ML36 VIERGE'!A51)),ISNUMBER(SEARCH("sans solde",'MATRICE ML36 VIERGE'!A52))),"Absence sans solde",IFERROR('MATRICE ML36 VIERGE'!F81,"")))),IF(OR('MATRICE ML37 VIERGE'!B50<>"",'MATRICE ML37 VIERGE'!B51<>""),IF(OR(ISNUMBER(SEARCH("maladie",'MATRICE ML37 VIERGE'!A50)),ISNUMBER(SEARCH("maladie",'MATRICE ML37 VIERGE'!A51))),"Maladie",IF(OR('MATRICE ML37 VIERGE'!A50="CA",'MATRICE ML37 VIERGE'!A51="CA",ISNUMBER(SEARCH("jem",'MATRICE ML37 VIERGE'!A50)),ISNUMBER(SEARCH("jem",'MATRICE ML37 VIERGE'!A51)),ISNUMBER(SEARCH("autres absence",'MATRICE ML37 VIERGE'!A50)),ISNUMBER(SEARCH("autres absence",'MATRICE ML37 VIERGE'!A51))),"Congés annuels",IF(OR(ISNUMBER(SEARCH("sans solde",'MATRICE ML37 VIERGE'!A50)),ISNUMBER(SEARCH("sans solde",'MATRICE ML37 VIERGE'!A51))),"Absence sans solde",IFERROR('MATRICE ML37 VIERGE'!F82,"")))),"")) | E32: =IF(OR('MATRICE ML36 VIERGE'!B51<>"",'MATRICE ML36 VIERGE'!B52<>""),IF(IFERROR('MATRICE ML36 VIERGE'!G81,0)=0,"",'MATRICE ML36 VIERGE'!G81),IF(OR('MATRICE ML37 VIERGE'!B50<>"",'MATRICE ML37 VIERGE'!B51<>""),IF(IFERROR('MATRICE ML37 VIERGE'!G82,0)=0,"",'MATRICE ML37 VIERGE'!G82),"")) | G32: =IF(OR('MATRICE ML36 VIERGE'!B51<>"",'MATRICE ML36 VIERGE'!B52<>""),IF(IFERROR('MATRICE ML36 VIERGE'!H81,0)=0,"",'MATRICE ML36 VIERGE'!H81),IF(OR('MATRICE ML37 VIERGE'!B50<>"",'MATRICE ML37 VIERGE'!B51<>""),IF(IFERROR('MATRICE ML37 VIERGE'!H82,0)=0,"",'MATRICE ML37 VIERGE'!H82),"")) | H32: =IF(OR(D32="",D32="Congés annuels",D32="Maladie",D32="Absence sans solde"),"",IF(OR('MATRICE ML36 VIERGE'!B51<>"",'MATRICE ML36 VIERGE'!B52<>""),IFERROR('MATRICE ML36 VIERGE'!$D$8,""),IF(OR('MATRICE ML37 VIERGE'!B50<>"",'MATRICE ML37 VIERGE'!B51<>""),IFERROR('MATRICE ML37 VIERGE'!$D$9,""),"")))
B34: (1) | C34: Salaires d'activité partielle (primes incluses) soumis à cotisation Prévoyance Maladie ;
B35: (2) | C35: A reconstituer en cas d'arrêt de travail sur la période considérée.
B36: Fait à : | C36: ROISSY CDG | F36: Cachet et Signature
B38: le : | C38: =NOW() -> 46228.647
B40: Nom du rédacteur :
B42: Téléphone :
B44: Mail : | C44: mail.csprh.vivinter@airfrance.fr
B46: Les informations recueillies font l’objet de traitements informatiques destinés à la passation, la promotion, la gestion et l’exécution des contrats proposés par
B47: notre groupe ainsi que le respect de nos obligations légales. Conformément à la loi «informatique et libertés» du 6 janvier 1978 modifiée en 2004, vous bénéficiez
B48: d’un droit d’accès et de rectification aux informations qui vous concernent, que vous pouvez exercer en vous adressant à :
B49: S2H – Service juridique – 18 rue de Courcelles 75384 Paris Cedex 08.
B51: A retourner à VIVINTER - Service Prevoyance - 82 rue Villeneuve - 92584 CLICHY Cedex - fax --> 01 70 91 39 37 - mail --> prevoyance@vivinter.fr
B53: M.L. : SIACI SAINT HONORE - SA à directoire et Conseil de Surveillance - Capital de 14 143 816 € - 18 rue de Courcelles - 75384 PARIS Cedex 08
B54: 572 059 939 RCS Paris - Courtage d'assurances - n° immatriculation ORIAS 07 000 771 - APE 6622 Z - n° de TVA Intracommunautaire : FR 54 572 059 939

Sheet MODOP Attestation VIV
A1: MOP OP Attestation Vivinter
A3: Ne compléter que les cases :
B5: N° DOSSIER
B6: Autres Primes
B7: Nom du rédacteur
B8: Téléphone
B9: Signature
A11: Envoi de l'attestation à Vivinter :
B14: Cliquer sur l'onglet "Fichier" en haut à gauche
B37: Cliquer sur "enregistrer une copie"
B61: Sélectionner où vous souhaitez l'enregistrer sur votre bureau en indiquant le nom du fichier voulu ET sélectionner en PDF :
B93: Vous pourrez ensuite enregistrer le fichier sur la GED et l'envoyer à vivinter via Neocase.
